<?xml version="1.0" ?>
<robot name='robot' xmlns:xacro="http://ros.org/wiki/xacro">

    <xacro:include filename="$(find robot_description)/urdf/gazebo.urdf.xacro" />
    <!--xacro:include filename="$(find robot_description)/urdf/lidar.urdf.xacro" /-->
    <!--xacro:include filename="$(find robot_description)/urdf/depth.urdf.xacro" /-->

    <!--<xacro:property name="chassis_length" value="0.335"/>#
    <xacro:property name="chassis_width" value="0.265"/>#
    <xacro:property name="chassis_height" value="0.138"/>#
    <xacro:property name="wheel_radius" value="0.033"/> #
    <xacro:property name="wheel_thickness" value="0.026"/>#
    <xacro:property name="wheel_mass" value="0.05"/>#
    <xacro:property name="wheel_offset_x" value="0.226"/>#
    <xacro:property name="wheel_offset_y" value="0.1485"/>#
    <xacro:property name="wheel_offset_z" value="0.01"/>#
    <xacro:property name="caster_wheel_radius" value="0.01"/>#
    <xacro:property name="caster_wheel_mass" value="0.01"/>#
    <xacro:property name="caster_wheel_offset_x" value="0.075"/>
    <xacro:property name="caster_wheel_offset_z" value="-0.013"/>
    <xacro:property name="mass" value="1.0"/> /-->

    <material name="white">
        <color rgba="1 1 1 1" />
    </material>

    <material name="orange">
        <color rgba="1 0.3 0.1 1"/>
    </material>

    <material name="blue">
        <color rgba="0.2 0.2 1 1"/>
    </material>

    <material name="black">
        <color rgba="0 0 0 1"/>
    </material>

    <material name="red">
        <color rgba="1 0 0 1"/>
    </material>

    <link name="base_link">
    </link>

    <link name="base_footprint">
    </link>

    <joint name="base_footprint_joint" type="fixed">
        <parent link="base_link"/>
        <child link="base_footprint"/>
        <origin xyz="0 0 -0.138" rpy="0 0 0"/>
    </joint>

    <joint name="chassis_joint" type="fixed">
        <parent link="base_link"/>
        <child link="chassis"/>
        <origin xyz="-0.226 0 -0.01"/>
    </joint>

    <link name='chassis'>
    
    <inertial>
        <origin xyz="0.1675 0 0.069" rpy="0 0 0"/>
        <mass value="1.0" />
        <inertia ixx="0.00743908" ixy="0.0" ixz="0.0"
                 iyy="0.0109391" iyz="0.0"
                 izz="0.0152042" />
    </inertial>
    <visual>
        <origin xyz="0.1775 0 0.069"/>
        <geometry>
            <box size="0.335 0.265 0.138"/>
        </geometry>
        <material name="orange"/>
    </visual>
    <collision>
        <origin xyz="0.1775 0 0.069"/>
        <geometry>
            <box size="0.335 0.265 0.138"/>
        </geometry>
    </collision>
    </link>

    <gazebo reference="chassis">
        <material>Gazebo/Orange</material>
    </gazebo>

    <joint name="left_wheel_joint" type="continuous">
        <parent link="base_link"/>
        <child link="left_wheel"/>
        <origin xyz="0 0.1485 0" rpy="-1.57075 0 0" />
        <axis xyz="0 0 1"/>
    </joint>

    <link name="left_wheel">
        <visual>
            <geometry>
                <cylinder radius="0.033" length="0.026"/>
            </geometry>
            <material name="blue"/>
        </visual>
        <collision>
            <geometry>
                <sphere radius="0.033"/>
            </geometry>
        </collision>
        <inertial>
            <origin xyz="0 0 0" rpy="0 0 0"/>
            <mass value="0.05" />
            <inertia ixx="1.64292e-5" ixy="0.0" ixz="0.0"
                     iyy="1.64292e-5" iyz="0.0"
                     izz="2.7225e-5" />
        </inertial>
    </link>

    <gazebo reference="left_wheel">
        <material>Gazebo/Blue</material>
    </gazebo>

    <joint name="right_wheel_joint" type="continuous">
        <parent link="base_link"/>
        <child link="right_wheel"/>
        <origin xyz="0 -0.1485 0" rpy="1.57075 0 0" />
        <axis xyz="0 0 -1"/>
    </joint>

    <link name="right_wheel">
        <visual>
            <geometry>
                <cylinder radius="0.033" length="0.026"/>
            </geometry>
            <material name="blue"/>
        </visual>
        <collision>
            <geometry>
                <sphere radius="0.033"/>
            </geometry>
        </collision>
        <inertial>
            <origin xyz="0 0 0" rpy="0 0 0"/>
            <mass value="${0.05}" />
            <inertia ixx="1.64292e-5" ixy="0.0" ixz="0.0"
                     iyy="1.64292e-5" iyz="0.0"
                     izz="2.7225e-5" />
        </inertial>
    </link>

    <gazebo reference="right_wheel">
        <material>Gazebo/Blue</material>
    </gazebo>

    <joint name="caster_wheel_joint" type="fixed">
        <parent link="chassis"/>
        <child link="caster_wheel"/>
        <origin xyz="0.075 0 -0.013"/>
    </joint>


    <link name="caster_wheel">
        <visual>
            <geometry>
                <sphere radius="0.01"/>
            </geometry>
            <material name="white"/>
        </visual>
        <collision>
            <geometry>
                <sphere radius="0.01"/>
            </geometry>
        </collision>
        <inertial>
            <origin xyz="0 0 0" rpy="0 0 0"/>
            <mass value="0.01" />
            <inertia ixx="4e-7" ixy="0.0" ixz="0.0"
                     iyy="4e-7" iyz="0.0"
                     izz="4e-7" />
        </inertial>
    </link>

    <gazebo reference="caster_wheel">
        <material>Gazebo/White</material>
        <mu1 value="0.001"/>
        <mu2 value="0.001"/>
    </gazebo>

</robot>
